<?xml version="1.0"?>
<robot name="ribot" xmlns:xacro="http://ros.org/wiki/xacro">

    <!-- ribot is a simple robotic system containing one rgb camera and an imu on top of a tripop.  -->

    <!-- Define  properties -->
    <xacro:property name="M_PI" value="3.1415926535897931" />
    <material name="Orange">
        <color rgba="1.0 0.4 0.0 1.0"/>
    </material>

    <!-- Colors -->
    <material name="tripod_color">
        <color rgba="0.21 0.21 .21 1"/>
    </material>

    <xacro:macro name="default_inertial">
        <inertial>
            <mass value="1"/>
            <inertia ixx="1.0" ixy="0.0" ixz="0.0" iyy="1.0" iyz="0.0" izz="1.0" />
        </inertial>
    </xacro:macro>

    <!-- Includes -->
    <xacro:include filename="$(find ribot_description)/urdf/robot.gazebo.xacro" />
    <xacro:include filename="$(find ribot_description)/urdf/rgb_camera.urdf.xacro" />
    <xacro:include filename="$(find ribot_description)/urdf/imu.urdf.xacro"/>

    <link name="base_link">
        <xacro:default_inertial />
    </link>

    <joint name="base_link_to_prismatic_x" type="prismatic">
        <origin xyz="0 0 0" rpy="0 0 0"/>
        <parent link="base_link"/>
        <child link="prismatic_x"/>
        <axis xyz="1 0 0"/>
        <limit effort="1000.0" lower="-0.38" upper="0" velocity="0.5"/>
    </joint>

    <link name="prismatic_x">
        <visual>
            <origin xyz="0 0 0" rpy="0 0 0" />
            <geometry>
                <box size="0.001 0.001 0.001" />
            </geometry>
        </visual>
        <collision>
            <origin xyz="0 0 0" rpy="0 0 0" />
            <geometry>
                <box size="0.001 0.001 0.001" />
            </geometry>
        </collision>
        <xacro:default_inertial />
        <gazebo>
            <gravity>0</gravity>
        </gazebo>
    </link>

    <joint name="prismatic_x_to_plate" type="fixed">
        <parent link="prismatic_x"/>
        <child link="plate"/>
        <origin xyz="0.1 0 0" rpy="0 0 0"/>
    </joint>

    <link name="plate">
        <visual>
            <origin xyz="0 0 0" rpy="0 0 0" />
            <geometry>
                <box size="0.04 0.4 0.015" />
            </geometry>
            <material name="tripod_color" />
        </visual>
        <collision name="tripod_collision">
            <origin xyz="0 0 0" rpy="0 0 0" />
            <geometry>
                <box size="0.04 0.15 0.015" />
            </geometry>
        </collision>
        <xacro:default_inertial />
    </link>


    <!-- GAZEBO -->
    <!-- ROS control plugin -->
    <gazebo>
        <plugin name="gazebo_ros_control" filename="libgazebo_ros_control.so">
            <namespace>/ribot</namespace>
        </plugin>
    </gazebo>

    <!-- Transmissions -->
    <transmission name="base_link_to_prismatic_x_trans">
        <type>transmission_interfact/SimpleTransmission</type>
        <actuator name="motor1">
            <mechanicalReduction>1</mechanicalReduction>
        </actuator>
        <joint name="base_link_to_prismatic_x">
            <hardwareInterface>hardware_interface/PositionJointInterface</hardwareInterface>
        </joint>
    </transmission>

    <!-- SENSORS -->
    <!-- Left IMU -->
    <!-- <xacro:imu parent="plate" prefix="imu" color_gazebo="Red"> -->
        <!-- <origin xyz="0.0 0.18 0.01" rpy="0 0 0" />           -->
        <!-- <color_rgb_rviz> -->
            <!-- <material name="red"> -->
                <!-- <color rgba="0.9 0 0 1" /> -->
            <!-- </material> -->
        <!-- </color_rgb_rviz> -->
    <!-- </xacro:imu> -->

    <!-- Right Camera -->
    <!-- <xacro:rgb_camera parent="plate" prefix="rgb_right" color_gazebo="Green"> -->
        <!-- <origin xyz="0.015 -0.18 0.0195" rpy="0 0 0" /> -->
        <!-- <color_rgb_rviz> -->
            <!-- <material name="green"> -->
                <!-- <color rgba="0 0.9 0 1" /> -->
            <!-- </material> -->
        <!-- </color_rgb_rviz> -->
    <!-- </xacro:rgb_camera> -->

</robot>